Sat 21 Dec 07:07:44 GMT 2024: Starting /home/torrobot/torrobot/sound.py...
Sat 21 Dec 07:07:44 GMT 2024: Starting /home/torrobot/torrobot/control.py...
Sat 21 Dec 07:07:44 GMT 2024: Starting /home/torrobot/torrobot/speaker.py...
Sat 21 Dec 07:07:44 GMT 2024: Starting /home/torrobot/torrobot/video.py...
Traceback (most recent call last):
  File "/home/torrobot/torrobot/venv/lib/python3.11/site-packages/gpiozero/pins/native.py", line 155, in __init__
    self.fd = os.open('/dev/gpiomem', os.O_RDWR | os.O_SYNC)
              ^^^^^^^^^^^^^^^^^^^^^^^^^^^^^^^^^^^^^^^^^^^^^^
FileNotFoundError: [Errno 2] No such file or directory: '/dev/gpiomem'

During handling of the above exception, another exception occurred:

Traceback (most recent call last):
  File "/home/torrobot/torrobot/venv/lib/python3.11/site-packages/gpiozero/pins/native.py", line 158, in __init__
    self.fd = os.open('/dev/mem', os.O_RDWR | os.O_SYNC)
              ^^^^^^^^^^^^^^^^^^^^^^^^^^^^^^^^^^^^^^^^^^
PermissionError: [Errno 13] Permission denied: '/dev/mem'

During handling of the above exception, another exception occurred:

Traceback (most recent call last):
  File "/home/torrobot/torrobot/control.py", line 9, in <module>
    Device.pin_factory = NativeFactory()
                         ^^^^^^^^^^^^^^^
  File "/home/torrobot/torrobot/venv/lib/python3.11/site-packages/gpiozero/pins/native.py", line 395, in __init__
    self.mem = GPIOMemory(self.board_info.soc)
               ^^^^^^^^^^^^^^^^^^^^^^^^^^^^^^^
  File "/home/torrobot/torrobot/venv/lib/python3.11/site-packages/gpiozero/pins/native.py", line 160, in __init__
    raise IOError(
OSError: unable to open /dev/gpiomem or /dev/mem; upgrade your kernel or run as root
Traceback (most recent call last):
  File "/home/torrobot/torrobot/speaker.py", line 59, in <module>
    asyncio.run(start_server())
  File "/usr/lib/python3.11/asyncio/runners.py", line 190, in run
    return runner.run(main)
           ^^^^^^^^^^^^^^^^
  File "/usr/lib/python3.11/asyncio/runners.py", line 118, in run
    return self._loop.run_until_complete(task)
           ^^^^^^^^^^^^^^^^^^^^^^^^^^^^^^^^^^^
  File "/usr/lib/python3.11/asyncio/base_events.py", line 653, in run_until_complete
    return future.result()
           ^^^^^^^^^^^^^^^
  File "/home/torrobot/torrobot/speaker.py", line 54, in start_server
    server = await websockets.serve(handle_audio_stream, "10.10.16.65", 8004)
             ^^^^^^^^^^^^^^^^^^^^^^^^^^^^^^^^^^^^^^^^^^^^^^^^^^^^^^^^^^^^^^^^
  File "/home/torrobot/torrobot/venv/lib/python3.11/site-packages/websockets/asyncio/server.py", line 825, in __await_impl__
    server = await self.create_server
             ^^^^^^^^^^^^^^^^^^^^^^^^
  File "/usr/lib/python3.11/asyncio/base_events.py", line 1525, in create_server
    raise OSError(err.errno, 'error while attempting '
OSError: [Errno 99] error while attempting to bind on address ('10.10.16.65', 8004): cannot assign requested address
Sat 21 Dec 07:07:45 GMT 2024: /home/torrobot/torrobot/control.py crashed with exit code 0; restarting in 5 seconds...
Sat 21 Dec 07:07:45 GMT 2024: /home/torrobot/torrobot/speaker.py crashed with exit code 0; restarting in 5 seconds...
Sat 21 Dec 07:07:50 GMT 2024: Starting /home/torrobot/torrobot/control.py...
Sat 21 Dec 07:07:50 GMT 2024: Starting /home/torrobot/torrobot/speaker.py...
Traceback (most recent call last):
  File "/home/torrobot/torrobot/venv/lib/python3.11/site-packages/gpiozero/pins/native.py", line 155, in __init__
    self.fd = os.open('/dev/gpiomem', os.O_RDWR | os.O_SYNC)
              ^^^^^^^^^^^^^^^^^^^^^^^^^^^^^^^^^^^^^^^^^^^^^^
FileNotFoundError: [Errno 2] No such file or directory: '/dev/gpiomem'

During handling of the above exception, another exception occurred:

Traceback (most recent call last):
  File "/home/torrobot/torrobot/venv/lib/python3.11/site-packages/gpiozero/pins/native.py", line 158, in __init__
    self.fd = os.open('/dev/mem', os.O_RDWR | os.O_SYNC)
              ^^^^^^^^^^^^^^^^^^^^^^^^^^^^^^^^^^^^^^^^^^
PermissionError: [Errno 13] Permission denied: '/dev/mem'

During handling of the above exception, another exception occurred:

Traceback (most recent call last):
  File "/home/torrobot/torrobot/control.py", line 9, in <module>
    Device.pin_factory = NativeFactory()
                         ^^^^^^^^^^^^^^^
  File "/home/torrobot/torrobot/venv/lib/python3.11/site-packages/gpiozero/pins/native.py", line 395, in __init__
    self.mem = GPIOMemory(self.board_info.soc)
               ^^^^^^^^^^^^^^^^^^^^^^^^^^^^^^^
  File "/home/torrobot/torrobot/venv/lib/python3.11/site-packages/gpiozero/pins/native.py", line 160, in __init__
    raise IOError(
OSError: unable to open /dev/gpiomem or /dev/mem; upgrade your kernel or run as root
Sat 21 Dec 07:07:50 GMT 2024: /home/torrobot/torrobot/control.py crashed with exit code 0; restarting in 5 seconds...
Traceback (most recent call last):
  File "/home/torrobot/torrobot/speaker.py", line 59, in <module>
    asyncio.run(start_server())
  File "/usr/lib/python3.11/asyncio/runners.py", line 190, in run
    return runner.run(main)
           ^^^^^^^^^^^^^^^^
  File "/usr/lib/python3.11/asyncio/runners.py", line 118, in run
    return self._loop.run_until_complete(task)
           ^^^^^^^^^^^^^^^^^^^^^^^^^^^^^^^^^^^
  File "/usr/lib/python3.11/asyncio/base_events.py", line 653, in run_until_complete
    return future.result()
           ^^^^^^^^^^^^^^^
  File "/home/torrobot/torrobot/speaker.py", line 54, in start_server
    server = await websockets.serve(handle_audio_stream, "10.10.16.65", 8004)
             ^^^^^^^^^^^^^^^^^^^^^^^^^^^^^^^^^^^^^^^^^^^^^^^^^^^^^^^^^^^^^^^^
  File "/home/torrobot/torrobot/venv/lib/python3.11/site-packages/websockets/asyncio/server.py", line 825, in __await_impl__
    server = await self.create_server
             ^^^^^^^^^^^^^^^^^^^^^^^^
  File "/usr/lib/python3.11/asyncio/base_events.py", line 1525, in create_server
    raise OSError(err.errno, 'error while attempting '
OSError: [Errno 99] error while attempting to bind on address ('10.10.16.65', 8004): cannot assign requested address
Sat 21 Dec 07:07:50 GMT 2024: /home/torrobot/torrobot/speaker.py crashed with exit code 0; restarting in 5 seconds...
Sat 21 Dec 07:07:55 GMT 2024: Starting /home/torrobot/torrobot/control.py...
Sat 21 Dec 07:07:55 GMT 2024: Starting /home/torrobot/torrobot/speaker.py...
Traceback (most recent call last):
  File "/home/torrobot/torrobot/venv/lib/python3.11/site-packages/gpiozero/pins/native.py", line 155, in __init__
    self.fd = os.open('/dev/gpiomem', os.O_RDWR | os.O_SYNC)
              ^^^^^^^^^^^^^^^^^^^^^^^^^^^^^^^^^^^^^^^^^^^^^^
FileNotFoundError: [Errno 2] No such file or directory: '/dev/gpiomem'

During handling of the above exception, another exception occurred:

Traceback (most recent call last):
  File "/home/torrobot/torrobot/venv/lib/python3.11/site-packages/gpiozero/pins/native.py", line 158, in __init__
    self.fd = os.open('/dev/mem', os.O_RDWR | os.O_SYNC)
              ^^^^^^^^^^^^^^^^^^^^^^^^^^^^^^^^^^^^^^^^^^
PermissionError: [Errno 13] Permission denied: '/dev/mem'

During handling of the above exception, another exception occurred:

Traceback (most recent call last):
  File "/home/torrobot/torrobot/control.py", line 9, in <module>
    Device.pin_factory = NativeFactory()
                         ^^^^^^^^^^^^^^^
  File "/home/torrobot/torrobot/venv/lib/python3.11/site-packages/gpiozero/pins/native.py", line 395, in __init__
    self.mem = GPIOMemory(self.board_info.soc)
               ^^^^^^^^^^^^^^^^^^^^^^^^^^^^^^^
  File "/home/torrobot/torrobot/venv/lib/python3.11/site-packages/gpiozero/pins/native.py", line 160, in __init__
    raise IOError(
OSError: unable to open /dev/gpiomem or /dev/mem; upgrade your kernel or run as root
Sat 21 Dec 07:07:55 GMT 2024: /home/torrobot/torrobot/control.py crashed with exit code 0; restarting in 5 seconds...
Sat 21 Dec 07:08:00 GMT 2024: Starting /home/torrobot/torrobot/control.py...
Traceback (most recent call last):
  File "/home/torrobot/torrobot/venv/lib/python3.11/site-packages/gpiozero/pins/native.py", line 155, in __init__
    self.fd = os.open('/dev/gpiomem', os.O_RDWR | os.O_SYNC)
              ^^^^^^^^^^^^^^^^^^^^^^^^^^^^^^^^^^^^^^^^^^^^^^
FileNotFoundError: [Errno 2] No such file or directory: '/dev/gpiomem'

During handling of the above exception, another exception occurred:

Traceback (most recent call last):
  File "/home/torrobot/torrobot/venv/lib/python3.11/site-packages/gpiozero/pins/native.py", line 158, in __init__
    self.fd = os.open('/dev/mem', os.O_RDWR | os.O_SYNC)
              ^^^^^^^^^^^^^^^^^^^^^^^^^^^^^^^^^^^^^^^^^^
PermissionError: [Errno 13] Permission denied: '/dev/mem'

During handling of the above exception, another exception occurred:

Traceback (most recent call last):
  File "/home/torrobot/torrobot/control.py", line 9, in <module>
    Device.pin_factory = NativeFactory()
                         ^^^^^^^^^^^^^^^
  File "/home/torrobot/torrobot/venv/lib/python3.11/site-packages/gpiozero/pins/native.py", line 395, in __init__
    self.mem = GPIOMemory(self.board_info.soc)
               ^^^^^^^^^^^^^^^^^^^^^^^^^^^^^^^
  File "/home/torrobot/torrobot/venv/lib/python3.11/site-packages/gpiozero/pins/native.py", line 160, in __init__
    raise IOError(
OSError: unable to open /dev/gpiomem or /dev/mem; upgrade your kernel or run as root
Sat 21 Dec 07:08:00 GMT 2024: /home/torrobot/torrobot/control.py crashed with exit code 0; restarting in 5 seconds...
Sat 21 Dec 07:08:05 GMT 2024: Starting /home/torrobot/torrobot/control.py...
Traceback (most recent call last):
  File "/home/torrobot/torrobot/venv/lib/python3.11/site-packages/gpiozero/pins/native.py", line 155, in __init__
    self.fd = os.open('/dev/gpiomem', os.O_RDWR | os.O_SYNC)
              ^^^^^^^^^^^^^^^^^^^^^^^^^^^^^^^^^^^^^^^^^^^^^^
FileNotFoundError: [Errno 2] No such file or directory: '/dev/gpiomem'

During handling of the above exception, another exception occurred:

Traceback (most recent call last):
  File "/home/torrobot/torrobot/venv/lib/python3.11/site-packages/gpiozero/pins/native.py", line 158, in __init__
    self.fd = os.open('/dev/mem', os.O_RDWR | os.O_SYNC)
              ^^^^^^^^^^^^^^^^^^^^^^^^^^^^^^^^^^^^^^^^^^
PermissionError: [Errno 13] Permission denied: '/dev/mem'

During handling of the above exception, another exception occurred:

Traceback (most recent call last):
  File "/home/torrobot/torrobot/control.py", line 9, in <module>
    Device.pin_factory = NativeFactory()
                         ^^^^^^^^^^^^^^^
  File "/home/torrobot/torrobot/venv/lib/python3.11/site-packages/gpiozero/pins/native.py", line 395, in __init__
    self.mem = GPIOMemory(self.board_info.soc)
               ^^^^^^^^^^^^^^^^^^^^^^^^^^^^^^^
  File "/home/torrobot/torrobot/venv/lib/python3.11/site-packages/gpiozero/pins/native.py", line 160, in __init__
    raise IOError(
OSError: unable to open /dev/gpiomem or /dev/mem; upgrade your kernel or run as root
Sat 21 Dec 07:08:05 GMT 2024: /home/torrobot/torrobot/control.py crashed with exit code 0; restarting in 5 seconds...
Sat 21 Dec 07:08:10 GMT 2024: Starting /home/torrobot/torrobot/control.py...
Traceback (most recent call last):
  File "/home/torrobot/torrobot/venv/lib/python3.11/site-packages/gpiozero/pins/native.py", line 155, in __init__
    self.fd = os.open('/dev/gpiomem', os.O_RDWR | os.O_SYNC)
              ^^^^^^^^^^^^^^^^^^^^^^^^^^^^^^^^^^^^^^^^^^^^^^
FileNotFoundError: [Errno 2] No such file or directory: '/dev/gpiomem'

During handling of the above exception, another exception occurred:

Traceback (most recent call last):
  File "/home/torrobot/torrobot/venv/lib/python3.11/site-packages/gpiozero/pins/native.py", line 158, in __init__
    self.fd = os.open('/dev/mem', os.O_RDWR | os.O_SYNC)
              ^^^^^^^^^^^^^^^^^^^^^^^^^^^^^^^^^^^^^^^^^^
PermissionError: [Errno 13] Permission denied: '/dev/mem'

During handling of the above exception, another exception occurred:

Traceback (most recent call last):
  File "/home/torrobot/torrobot/control.py", line 9, in <module>
    Device.pin_factory = NativeFactory()
                         ^^^^^^^^^^^^^^^
  File "/home/torrobot/torrobot/venv/lib/python3.11/site-packages/gpiozero/pins/native.py", line 395, in __init__
    self.mem = GPIOMemory(self.board_info.soc)
               ^^^^^^^^^^^^^^^^^^^^^^^^^^^^^^^
  File "/home/torrobot/torrobot/venv/lib/python3.11/site-packages/gpiozero/pins/native.py", line 160, in __init__
    raise IOError(
OSError: unable to open /dev/gpiomem or /dev/mem; upgrade your kernel or run as root
Sat 21 Dec 07:08:11 GMT 2024: /home/torrobot/torrobot/control.py crashed with exit code 0; restarting in 5 seconds...
Sat 21 Dec 07:08:15 GMT 2024: Starting /home/torrobot/torrobot/control.py...
Traceback (most recent call last):
  File "/home/torrobot/torrobot/venv/lib/python3.11/site-packages/gpiozero/pins/native.py", line 155, in __init__
    self.fd = os.open('/dev/gpiomem', os.O_RDWR | os.O_SYNC)
              ^^^^^^^^^^^^^^^^^^^^^^^^^^^^^^^^^^^^^^^^^^^^^^
FileNotFoundError: [Errno 2] No such file or directory: '/dev/gpiomem'

During handling of the above exception, another exception occurred:

Traceback (most recent call last):
  File "/home/torrobot/torrobot/venv/lib/python3.11/site-packages/gpiozero/pins/native.py", line 158, in __init__
    self.fd = os.open('/dev/mem', os.O_RDWR | os.O_SYNC)
              ^^^^^^^^^^^^^^^^^^^^^^^^^^^^^^^^^^^^^^^^^^
PermissionError: [Errno 13] Permission denied: '/dev/mem'

During handling of the above exception, another exception occurred:

Traceback (most recent call last):
  File "/home/torrobot/torrobot/control.py", line 9, in <module>
    Device.pin_factory = NativeFactory()
                         ^^^^^^^^^^^^^^^
  File "/home/torrobot/torrobot/venv/lib/python3.11/site-packages/gpiozero/pins/native.py", line 395, in __init__
    self.mem = GPIOMemory(self.board_info.soc)
               ^^^^^^^^^^^^^^^^^^^^^^^^^^^^^^^
  File "/home/torrobot/torrobot/venv/lib/python3.11/site-packages/gpiozero/pins/native.py", line 160, in __init__
    raise IOError(
OSError: unable to open /dev/gpiomem or /dev/mem; upgrade your kernel or run as root
Sat 21 Dec 07:08:15 GMT 2024: /home/torrobot/torrobot/control.py crashed with exit code 0; restarting in 5 seconds...
Sat 21 Dec 07:08:20 GMT 2024: Starting /home/torrobot/torrobot/control.py...
Traceback (most recent call last):
  File "/home/torrobot/torrobot/venv/lib/python3.11/site-packages/gpiozero/pins/native.py", line 155, in __init__
    self.fd = os.open('/dev/gpiomem', os.O_RDWR | os.O_SYNC)
              ^^^^^^^^^^^^^^^^^^^^^^^^^^^^^^^^^^^^^^^^^^^^^^
FileNotFoundError: [Errno 2] No such file or directory: '/dev/gpiomem'

During handling of the above exception, another exception occurred:

Traceback (most recent call last):
  File "/home/torrobot/torrobot/venv/lib/python3.11/site-packages/gpiozero/pins/native.py", line 158, in __init__
    self.fd = os.open('/dev/mem', os.O_RDWR | os.O_SYNC)
              ^^^^^^^^^^^^^^^^^^^^^^^^^^^^^^^^^^^^^^^^^^
PermissionError: [Errno 13] Permission denied: '/dev/mem'

During handling of the above exception, another exception occurred:

Traceback (most recent call last):
  File "/home/torrobot/torrobot/control.py", line 9, in <module>
    Device.pin_factory = NativeFactory()
                         ^^^^^^^^^^^^^^^
  File "/home/torrobot/torrobot/venv/lib/python3.11/site-packages/gpiozero/pins/native.py", line 395, in __init__
    self.mem = GPIOMemory(self.board_info.soc)
               ^^^^^^^^^^^^^^^^^^^^^^^^^^^^^^^
  File "/home/torrobot/torrobot/venv/lib/python3.11/site-packages/gpiozero/pins/native.py", line 160, in __init__
    raise IOError(
OSError: unable to open /dev/gpiomem or /dev/mem; upgrade your kernel or run as root
Sat 21 Dec 07:08:20 GMT 2024: /home/torrobot/torrobot/control.py crashed with exit code 0; restarting in 5 seconds...
Sat 21 Dec 07:08:25 GMT 2024: Starting /home/torrobot/torrobot/control.py...
Traceback (most recent call last):
  File "/home/torrobot/torrobot/venv/lib/python3.11/site-packages/gpiozero/pins/native.py", line 155, in __init__
    self.fd = os.open('/dev/gpiomem', os.O_RDWR | os.O_SYNC)
              ^^^^^^^^^^^^^^^^^^^^^^^^^^^^^^^^^^^^^^^^^^^^^^
FileNotFoundError: [Errno 2] No such file or directory: '/dev/gpiomem'

During handling of the above exception, another exception occurred:

Traceback (most recent call last):
  File "/home/torrobot/torrobot/venv/lib/python3.11/site-packages/gpiozero/pins/native.py", line 158, in __init__
    self.fd = os.open('/dev/mem', os.O_RDWR | os.O_SYNC)
              ^^^^^^^^^^^^^^^^^^^^^^^^^^^^^^^^^^^^^^^^^^
PermissionError: [Errno 13] Permission denied: '/dev/mem'

During handling of the above exception, another exception occurred:

Traceback (most recent call last):
  File "/home/torrobot/torrobot/control.py", line 9, in <module>
    Device.pin_factory = NativeFactory()
                         ^^^^^^^^^^^^^^^
  File "/home/torrobot/torrobot/venv/lib/python3.11/site-packages/gpiozero/pins/native.py", line 395, in __init__
    self.mem = GPIOMemory(self.board_info.soc)
               ^^^^^^^^^^^^^^^^^^^^^^^^^^^^^^^
  File "/home/torrobot/torrobot/venv/lib/python3.11/site-packages/gpiozero/pins/native.py", line 160, in __init__
    raise IOError(
OSError: unable to open /dev/gpiomem or /dev/mem; upgrade your kernel or run as root
Sat 21 Dec 07:08:26 GMT 2024: /home/torrobot/torrobot/control.py crashed with exit code 0; restarting in 5 seconds...
Sat 21 Dec 07:08:31 GMT 2024: Starting /home/torrobot/torrobot/control.py...
Traceback (most recent call last):
  File "/home/torrobot/torrobot/venv/lib/python3.11/site-packages/gpiozero/pins/native.py", line 155, in __init__
    self.fd = os.open('/dev/gpiomem', os.O_RDWR | os.O_SYNC)
              ^^^^^^^^^^^^^^^^^^^^^^^^^^^^^^^^^^^^^^^^^^^^^^
FileNotFoundError: [Errno 2] No such file or directory: '/dev/gpiomem'

During handling of the above exception, another exception occurred:

Traceback (most recent call last):
  File "/home/torrobot/torrobot/venv/lib/python3.11/site-packages/gpiozero/pins/native.py", line 158, in __init__
    self.fd = os.open('/dev/mem', os.O_RDWR | os.O_SYNC)
              ^^^^^^^^^^^^^^^^^^^^^^^^^^^^^^^^^^^^^^^^^^
PermissionError: [Errno 13] Permission denied: '/dev/mem'

During handling of the above exception, another exception occurred:

Traceback (most recent call last):
  File "/home/torrobot/torrobot/control.py", line 9, in <module>
    Device.pin_factory = NativeFactory()
                         ^^^^^^^^^^^^^^^
  File "/home/torrobot/torrobot/venv/lib/python3.11/site-packages/gpiozero/pins/native.py", line 395, in __init__
    self.mem = GPIOMemory(self.board_info.soc)
               ^^^^^^^^^^^^^^^^^^^^^^^^^^^^^^^
  File "/home/torrobot/torrobot/venv/lib/python3.11/site-packages/gpiozero/pins/native.py", line 160, in __init__
    raise IOError(
OSError: unable to open /dev/gpiomem or /dev/mem; upgrade your kernel or run as root
Sat 21 Dec 07:08:31 GMT 2024: /home/torrobot/torrobot/control.py crashed with exit code 0; restarting in 5 seconds...
Sat 21 Dec 07:08:36 GMT 2024: Starting /home/torrobot/torrobot/control.py...
Traceback (most recent call last):
  File "/home/torrobot/torrobot/venv/lib/python3.11/site-packages/gpiozero/pins/native.py", line 155, in __init__
    self.fd = os.open('/dev/gpiomem', os.O_RDWR | os.O_SYNC)
              ^^^^^^^^^^^^^^^^^^^^^^^^^^^^^^^^^^^^^^^^^^^^^^
FileNotFoundError: [Errno 2] No such file or directory: '/dev/gpiomem'

During handling of the above exception, another exception occurred:

Traceback (most recent call last):
  File "/home/torrobot/torrobot/venv/lib/python3.11/site-packages/gpiozero/pins/native.py", line 158, in __init__
    self.fd = os.open('/dev/mem', os.O_RDWR | os.O_SYNC)
              ^^^^^^^^^^^^^^^^^^^^^^^^^^^^^^^^^^^^^^^^^^
PermissionError: [Errno 13] Permission denied: '/dev/mem'

During handling of the above exception, another exception occurred:

Traceback (most recent call last):
  File "/home/torrobot/torrobot/control.py", line 9, in <module>
    Device.pin_factory = NativeFactory()
                         ^^^^^^^^^^^^^^^
  File "/home/torrobot/torrobot/venv/lib/python3.11/site-packages/gpiozero/pins/native.py", line 395, in __init__
    self.mem = GPIOMemory(self.board_info.soc)
               ^^^^^^^^^^^^^^^^^^^^^^^^^^^^^^^
  File "/home/torrobot/torrobot/venv/lib/python3.11/site-packages/gpiozero/pins/native.py", line 160, in __init__
    raise IOError(
OSError: unable to open /dev/gpiomem or /dev/mem; upgrade your kernel or run as root
Sat 21 Dec 07:08:36 GMT 2024: /home/torrobot/torrobot/control.py crashed with exit code 0; restarting in 5 seconds...
Sat 21 Dec 07:08:41 GMT 2024: Starting /home/torrobot/torrobot/control.py...
Traceback (most recent call last):
  File "/home/torrobot/torrobot/venv/lib/python3.11/site-packages/gpiozero/pins/native.py", line 155, in __init__
    self.fd = os.open('/dev/gpiomem', os.O_RDWR | os.O_SYNC)
              ^^^^^^^^^^^^^^^^^^^^^^^^^^^^^^^^^^^^^^^^^^^^^^
FileNotFoundError: [Errno 2] No such file or directory: '/dev/gpiomem'

During handling of the above exception, another exception occurred:

Traceback (most recent call last):
  File "/home/torrobot/torrobot/venv/lib/python3.11/site-packages/gpiozero/pins/native.py", line 158, in __init__
    self.fd = os.open('/dev/mem', os.O_RDWR | os.O_SYNC)
              ^^^^^^^^^^^^^^^^^^^^^^^^^^^^^^^^^^^^^^^^^^
PermissionError: [Errno 13] Permission denied: '/dev/mem'

During handling of the above exception, another exception occurred:

Traceback (most recent call last):
  File "/home/torrobot/torrobot/control.py", line 9, in <module>
    Device.pin_factory = NativeFactory()
                         ^^^^^^^^^^^^^^^
  File "/home/torrobot/torrobot/venv/lib/python3.11/site-packages/gpiozero/pins/native.py", line 395, in __init__
    self.mem = GPIOMemory(self.board_info.soc)
               ^^^^^^^^^^^^^^^^^^^^^^^^^^^^^^^
  File "/home/torrobot/torrobot/venv/lib/python3.11/site-packages/gpiozero/pins/native.py", line 160, in __init__
    raise IOError(
OSError: unable to open /dev/gpiomem or /dev/mem; upgrade your kernel or run as root
Sat 21 Dec 07:08:41 GMT 2024: /home/torrobot/torrobot/control.py crashed with exit code 0; restarting in 5 seconds...
Sat 21 Dec 07:08:46 GMT 2024: Starting /home/torrobot/torrobot/control.py...
Traceback (most recent call last):
  File "/home/torrobot/torrobot/venv/lib/python3.11/site-packages/gpiozero/pins/native.py", line 155, in __init__
    self.fd = os.open('/dev/gpiomem', os.O_RDWR | os.O_SYNC)
              ^^^^^^^^^^^^^^^^^^^^^^^^^^^^^^^^^^^^^^^^^^^^^^
FileNotFoundError: [Errno 2] No such file or directory: '/dev/gpiomem'

During handling of the above exception, another exception occurred:

Traceback (most recent call last):
  File "/home/torrobot/torrobot/venv/lib/python3.11/site-packages/gpiozero/pins/native.py", line 158, in __init__
    self.fd = os.open('/dev/mem', os.O_RDWR | os.O_SYNC)
              ^^^^^^^^^^^^^^^^^^^^^^^^^^^^^^^^^^^^^^^^^^
PermissionError: [Errno 13] Permission denied: '/dev/mem'

During handling of the above exception, another exception occurred:

Traceback (most recent call last):
  File "/home/torrobot/torrobot/control.py", line 9, in <module>
    Device.pin_factory = NativeFactory()
                         ^^^^^^^^^^^^^^^
  File "/home/torrobot/torrobot/venv/lib/python3.11/site-packages/gpiozero/pins/native.py", line 395, in __init__
    self.mem = GPIOMemory(self.board_info.soc)
               ^^^^^^^^^^^^^^^^^^^^^^^^^^^^^^^
  File "/home/torrobot/torrobot/venv/lib/python3.11/site-packages/gpiozero/pins/native.py", line 160, in __init__
    raise IOError(
OSError: unable to open /dev/gpiomem or /dev/mem; upgrade your kernel or run as root
Sat 21 Dec 07:08:46 GMT 2024: /home/torrobot/torrobot/control.py crashed with exit code 0; restarting in 5 seconds...
Sat 21 Dec 07:08:51 GMT 2024: Starting /home/torrobot/torrobot/control.py...
Traceback (most recent call last):
  File "/home/torrobot/torrobot/venv/lib/python3.11/site-packages/gpiozero/pins/native.py", line 155, in __init__
    self.fd = os.open('/dev/gpiomem', os.O_RDWR | os.O_SYNC)
              ^^^^^^^^^^^^^^^^^^^^^^^^^^^^^^^^^^^^^^^^^^^^^^
FileNotFoundError: [Errno 2] No such file or directory: '/dev/gpiomem'

During handling of the above exception, another exception occurred:

Traceback (most recent call last):
  File "/home/torrobot/torrobot/venv/lib/python3.11/site-packages/gpiozero/pins/native.py", line 158, in __init__
    self.fd = os.open('/dev/mem', os.O_RDWR | os.O_SYNC)
              ^^^^^^^^^^^^^^^^^^^^^^^^^^^^^^^^^^^^^^^^^^
PermissionError: [Errno 13] Permission denied: '/dev/mem'

During handling of the above exception, another exception occurred:

Traceback (most recent call last):
  File "/home/torrobot/torrobot/control.py", line 9, in <module>
    Device.pin_factory = NativeFactory()
                         ^^^^^^^^^^^^^^^
  File "/home/torrobot/torrobot/venv/lib/python3.11/site-packages/gpiozero/pins/native.py", line 395, in __init__
    self.mem = GPIOMemory(self.board_info.soc)
               ^^^^^^^^^^^^^^^^^^^^^^^^^^^^^^^
  File "/home/torrobot/torrobot/venv/lib/python3.11/site-packages/gpiozero/pins/native.py", line 160, in __init__
    raise IOError(
OSError: unable to open /dev/gpiomem or /dev/mem; upgrade your kernel or run as root
Sat 21 Dec 07:08:51 GMT 2024: /home/torrobot/torrobot/control.py crashed with exit code 0; restarting in 5 seconds...
Sat 21 Dec 07:08:56 GMT 2024: Starting /home/torrobot/torrobot/control.py...
Traceback (most recent call last):
  File "/home/torrobot/torrobot/venv/lib/python3.11/site-packages/gpiozero/pins/native.py", line 155, in __init__
    self.fd = os.open('/dev/gpiomem', os.O_RDWR | os.O_SYNC)
              ^^^^^^^^^^^^^^^^^^^^^^^^^^^^^^^^^^^^^^^^^^^^^^
FileNotFoundError: [Errno 2] No such file or directory: '/dev/gpiomem'

During handling of the above exception, another exception occurred:

Traceback (most recent call last):
  File "/home/torrobot/torrobot/venv/lib/python3.11/site-packages/gpiozero/pins/native.py", line 158, in __init__
    self.fd = os.open('/dev/mem', os.O_RDWR | os.O_SYNC)
              ^^^^^^^^^^^^^^^^^^^^^^^^^^^^^^^^^^^^^^^^^^
PermissionError: [Errno 13] Permission denied: '/dev/mem'

During handling of the above exception, another exception occurred:

Traceback (most recent call last):
  File "/home/torrobot/torrobot/control.py", line 9, in <module>
    Device.pin_factory = NativeFactory()
                         ^^^^^^^^^^^^^^^
  File "/home/torrobot/torrobot/venv/lib/python3.11/site-packages/gpiozero/pins/native.py", line 395, in __init__
    self.mem = GPIOMemory(self.board_info.soc)
               ^^^^^^^^^^^^^^^^^^^^^^^^^^^^^^^
  File "/home/torrobot/torrobot/venv/lib/python3.11/site-packages/gpiozero/pins/native.py", line 160, in __init__
    raise IOError(
OSError: unable to open /dev/gpiomem or /dev/mem; upgrade your kernel or run as root
Sat 21 Dec 07:08:57 GMT 2024: /home/torrobot/torrobot/control.py crashed with exit code 0; restarting in 5 seconds...
Sat 21 Dec 07:09:02 GMT 2024: Starting /home/torrobot/torrobot/control.py...
Traceback (most recent call last):
  File "/home/torrobot/torrobot/venv/lib/python3.11/site-packages/gpiozero/pins/native.py", line 155, in __init__
    self.fd = os.open('/dev/gpiomem', os.O_RDWR | os.O_SYNC)
              ^^^^^^^^^^^^^^^^^^^^^^^^^^^^^^^^^^^^^^^^^^^^^^
FileNotFoundError: [Errno 2] No such file or directory: '/dev/gpiomem'

During handling of the above exception, another exception occurred:

Traceback (most recent call last):
  File "/home/torrobot/torrobot/venv/lib/python3.11/site-packages/gpiozero/pins/native.py", line 158, in __init__
    self.fd = os.open('/dev/mem', os.O_RDWR | os.O_SYNC)
              ^^^^^^^^^^^^^^^^^^^^^^^^^^^^^^^^^^^^^^^^^^
PermissionError: [Errno 13] Permission denied: '/dev/mem'

During handling of the above exception, another exception occurred:

Traceback (most recent call last):
  File "/home/torrobot/torrobot/control.py", line 9, in <module>
    Device.pin_factory = NativeFactory()
                         ^^^^^^^^^^^^^^^
  File "/home/torrobot/torrobot/venv/lib/python3.11/site-packages/gpiozero/pins/native.py", line 395, in __init__
    self.mem = GPIOMemory(self.board_info.soc)
               ^^^^^^^^^^^^^^^^^^^^^^^^^^^^^^^
  File "/home/torrobot/torrobot/venv/lib/python3.11/site-packages/gpiozero/pins/native.py", line 160, in __init__
    raise IOError(
OSError: unable to open /dev/gpiomem or /dev/mem; upgrade your kernel or run as root
Sat 21 Dec 07:09:02 GMT 2024: /home/torrobot/torrobot/control.py crashed with exit code 0; restarting in 5 seconds...
Sat 21 Dec 07:09:07 GMT 2024: Starting /home/torrobot/torrobot/control.py...
Traceback (most recent call last):
  File "/home/torrobot/torrobot/venv/lib/python3.11/site-packages/gpiozero/pins/native.py", line 155, in __init__
    self.fd = os.open('/dev/gpiomem', os.O_RDWR | os.O_SYNC)
              ^^^^^^^^^^^^^^^^^^^^^^^^^^^^^^^^^^^^^^^^^^^^^^
FileNotFoundError: [Errno 2] No such file or directory: '/dev/gpiomem'

During handling of the above exception, another exception occurred:

Traceback (most recent call last):
  File "/home/torrobot/torrobot/venv/lib/python3.11/site-packages/gpiozero/pins/native.py", line 158, in __init__
    self.fd = os.open('/dev/mem', os.O_RDWR | os.O_SYNC)
              ^^^^^^^^^^^^^^^^^^^^^^^^^^^^^^^^^^^^^^^^^^
PermissionError: [Errno 13] Permission denied: '/dev/mem'

During handling of the above exception, another exception occurred:

Traceback (most recent call last):
  File "/home/torrobot/torrobot/control.py", line 9, in <module>
    Device.pin_factory = NativeFactory()
                         ^^^^^^^^^^^^^^^
  File "/home/torrobot/torrobot/venv/lib/python3.11/site-packages/gpiozero/pins/native.py", line 395, in __init__
    self.mem = GPIOMemory(self.board_info.soc)
               ^^^^^^^^^^^^^^^^^^^^^^^^^^^^^^^
  File "/home/torrobot/torrobot/venv/lib/python3.11/site-packages/gpiozero/pins/native.py", line 160, in __init__
    raise IOError(
OSError: unable to open /dev/gpiomem or /dev/mem; upgrade your kernel or run as root
Sat 21 Dec 07:09:07 GMT 2024: /home/torrobot/torrobot/control.py crashed with exit code 0; restarting in 5 seconds...
Sat 21 Dec 07:09:12 GMT 2024: Starting /home/torrobot/torrobot/control.py...
Traceback (most recent call last):
  File "/home/torrobot/torrobot/venv/lib/python3.11/site-packages/gpiozero/pins/native.py", line 155, in __init__
    self.fd = os.open('/dev/gpiomem', os.O_RDWR | os.O_SYNC)
              ^^^^^^^^^^^^^^^^^^^^^^^^^^^^^^^^^^^^^^^^^^^^^^
FileNotFoundError: [Errno 2] No such file or directory: '/dev/gpiomem'

During handling of the above exception, another exception occurred:

Traceback (most recent call last):
  File "/home/torrobot/torrobot/venv/lib/python3.11/site-packages/gpiozero/pins/native.py", line 158, in __init__
    self.fd = os.open('/dev/mem', os.O_RDWR | os.O_SYNC)
              ^^^^^^^^^^^^^^^^^^^^^^^^^^^^^^^^^^^^^^^^^^
PermissionError: [Errno 13] Permission denied: '/dev/mem'

During handling of the above exception, another exception occurred:

Traceback (most recent call last):
  File "/home/torrobot/torrobot/control.py", line 9, in <module>
    Device.pin_factory = NativeFactory()
                         ^^^^^^^^^^^^^^^
  File "/home/torrobot/torrobot/venv/lib/python3.11/site-packages/gpiozero/pins/native.py", line 395, in __init__
    self.mem = GPIOMemory(self.board_info.soc)
               ^^^^^^^^^^^^^^^^^^^^^^^^^^^^^^^
  File "/home/torrobot/torrobot/venv/lib/python3.11/site-packages/gpiozero/pins/native.py", line 160, in __init__
    raise IOError(
OSError: unable to open /dev/gpiomem or /dev/mem; upgrade your kernel or run as root
Sat 21 Dec 07:09:12 GMT 2024: /home/torrobot/torrobot/control.py crashed with exit code 0; restarting in 5 seconds...
Sat 21 Dec 07:09:17 GMT 2024: Starting /home/torrobot/torrobot/control.py...
Traceback (most recent call last):
  File "/home/torrobot/torrobot/venv/lib/python3.11/site-packages/gpiozero/pins/native.py", line 155, in __init__
    self.fd = os.open('/dev/gpiomem', os.O_RDWR | os.O_SYNC)
              ^^^^^^^^^^^^^^^^^^^^^^^^^^^^^^^^^^^^^^^^^^^^^^
FileNotFoundError: [Errno 2] No such file or directory: '/dev/gpiomem'

During handling of the above exception, another exception occurred:

Traceback (most recent call last):
  File "/home/torrobot/torrobot/venv/lib/python3.11/site-packages/gpiozero/pins/native.py", line 158, in __init__
    self.fd = os.open('/dev/mem', os.O_RDWR | os.O_SYNC)
              ^^^^^^^^^^^^^^^^^^^^^^^^^^^^^^^^^^^^^^^^^^
PermissionError: [Errno 13] Permission denied: '/dev/mem'

During handling of the above exception, another exception occurred:

Traceback (most recent call last):
  File "/home/torrobot/torrobot/control.py", line 9, in <module>
    Device.pin_factory = NativeFactory()
                         ^^^^^^^^^^^^^^^
  File "/home/torrobot/torrobot/venv/lib/python3.11/site-packages/gpiozero/pins/native.py", line 395, in __init__
    self.mem = GPIOMemory(self.board_info.soc)
               ^^^^^^^^^^^^^^^^^^^^^^^^^^^^^^^
  File "/home/torrobot/torrobot/venv/lib/python3.11/site-packages/gpiozero/pins/native.py", line 160, in __init__
    raise IOError(
OSError: unable to open /dev/gpiomem or /dev/mem; upgrade your kernel or run as root
Sat 21 Dec 07:09:17 GMT 2024: /home/torrobot/torrobot/control.py crashed with exit code 0; restarting in 5 seconds...
Sat 21 Dec 07:09:22 GMT 2024: Starting /home/torrobot/torrobot/control.py...
Traceback (most recent call last):
  File "/home/torrobot/torrobot/venv/lib/python3.11/site-packages/gpiozero/pins/native.py", line 155, in __init__
    self.fd = os.open('/dev/gpiomem', os.O_RDWR | os.O_SYNC)
              ^^^^^^^^^^^^^^^^^^^^^^^^^^^^^^^^^^^^^^^^^^^^^^
FileNotFoundError: [Errno 2] No such file or directory: '/dev/gpiomem'

During handling of the above exception, another exception occurred:

Traceback (most recent call last):
  File "/home/torrobot/torrobot/venv/lib/python3.11/site-packages/gpiozero/pins/native.py", line 158, in __init__
    self.fd = os.open('/dev/mem', os.O_RDWR | os.O_SYNC)
              ^^^^^^^^^^^^^^^^^^^^^^^^^^^^^^^^^^^^^^^^^^
PermissionError: [Errno 13] Permission denied: '/dev/mem'

During handling of the above exception, another exception occurred:

Traceback (most recent call last):
  File "/home/torrobot/torrobot/control.py", line 9, in <module>
    Device.pin_factory = NativeFactory()
                         ^^^^^^^^^^^^^^^
  File "/home/torrobot/torrobot/venv/lib/python3.11/site-packages/gpiozero/pins/native.py", line 395, in __init__
    self.mem = GPIOMemory(self.board_info.soc)
               ^^^^^^^^^^^^^^^^^^^^^^^^^^^^^^^
  File "/home/torrobot/torrobot/venv/lib/python3.11/site-packages/gpiozero/pins/native.py", line 160, in __init__
    raise IOError(
OSError: unable to open /dev/gpiomem or /dev/mem; upgrade your kernel or run as root
Sat 21 Dec 07:09:23 GMT 2024: /home/torrobot/torrobot/control.py crashed with exit code 0; restarting in 5 seconds...
Sat 21 Dec 07:09:28 GMT 2024: Starting /home/torrobot/torrobot/control.py...
Traceback (most recent call last):
  File "/home/torrobot/torrobot/venv/lib/python3.11/site-packages/gpiozero/pins/native.py", line 155, in __init__
    self.fd = os.open('/dev/gpiomem', os.O_RDWR | os.O_SYNC)
              ^^^^^^^^^^^^^^^^^^^^^^^^^^^^^^^^^^^^^^^^^^^^^^
FileNotFoundError: [Errno 2] No such file or directory: '/dev/gpiomem'

During handling of the above exception, another exception occurred:

Traceback (most recent call last):
  File "/home/torrobot/torrobot/venv/lib/python3.11/site-packages/gpiozero/pins/native.py", line 158, in __init__
    self.fd = os.open('/dev/mem', os.O_RDWR | os.O_SYNC)
              ^^^^^^^^^^^^^^^^^^^^^^^^^^^^^^^^^^^^^^^^^^
PermissionError: [Errno 13] Permission denied: '/dev/mem'

During handling of the above exception, another exception occurred:

Traceback (most recent call last):
  File "/home/torrobot/torrobot/control.py", line 9, in <module>
    Device.pin_factory = NativeFactory()
                         ^^^^^^^^^^^^^^^
  File "/home/torrobot/torrobot/venv/lib/python3.11/site-packages/gpiozero/pins/native.py", line 395, in __init__
    self.mem = GPIOMemory(self.board_info.soc)
               ^^^^^^^^^^^^^^^^^^^^^^^^^^^^^^^
  File "/home/torrobot/torrobot/venv/lib/python3.11/site-packages/gpiozero/pins/native.py", line 160, in __init__
    raise IOError(
OSError: unable to open /dev/gpiomem or /dev/mem; upgrade your kernel or run as root
Sat 21 Dec 07:09:28 GMT 2024: /home/torrobot/torrobot/control.py crashed with exit code 0; restarting in 5 seconds...
Sat 21 Dec 07:09:33 GMT 2024: Starting /home/torrobot/torrobot/control.py...
Traceback (most recent call last):
  File "/home/torrobot/torrobot/venv/lib/python3.11/site-packages/gpiozero/pins/native.py", line 155, in __init__
    self.fd = os.open('/dev/gpiomem', os.O_RDWR | os.O_SYNC)
              ^^^^^^^^^^^^^^^^^^^^^^^^^^^^^^^^^^^^^^^^^^^^^^
FileNotFoundError: [Errno 2] No such file or directory: '/dev/gpiomem'

During handling of the above exception, another exception occurred:

Traceback (most recent call last):
  File "/home/torrobot/torrobot/venv/lib/python3.11/site-packages/gpiozero/pins/native.py", line 158, in __init__
    self.fd = os.open('/dev/mem', os.O_RDWR | os.O_SYNC)
              ^^^^^^^^^^^^^^^^^^^^^^^^^^^^^^^^^^^^^^^^^^
PermissionError: [Errno 13] Permission denied: '/dev/mem'

During handling of the above exception, another exception occurred:

Traceback (most recent call last):
  File "/home/torrobot/torrobot/control.py", line 9, in <module>
    Device.pin_factory = NativeFactory()
                         ^^^^^^^^^^^^^^^
  File "/home/torrobot/torrobot/venv/lib/python3.11/site-packages/gpiozero/pins/native.py", line 395, in __init__
    self.mem = GPIOMemory(self.board_info.soc)
               ^^^^^^^^^^^^^^^^^^^^^^^^^^^^^^^
  File "/home/torrobot/torrobot/venv/lib/python3.11/site-packages/gpiozero/pins/native.py", line 160, in __init__
    raise IOError(
OSError: unable to open /dev/gpiomem or /dev/mem; upgrade your kernel or run as root
Sat 21 Dec 07:09:33 GMT 2024: /home/torrobot/torrobot/control.py crashed with exit code 0; restarting in 5 seconds...
Sat 21 Dec 07:09:38 GMT 2024: Starting /home/torrobot/torrobot/control.py...
Traceback (most recent call last):
  File "/home/torrobot/torrobot/venv/lib/python3.11/site-packages/gpiozero/pins/native.py", line 155, in __init__
    self.fd = os.open('/dev/gpiomem', os.O_RDWR | os.O_SYNC)
              ^^^^^^^^^^^^^^^^^^^^^^^^^^^^^^^^^^^^^^^^^^^^^^
FileNotFoundError: [Errno 2] No such file or directory: '/dev/gpiomem'

During handling of the above exception, another exception occurred:

Traceback (most recent call last):
  File "/home/torrobot/torrobot/venv/lib/python3.11/site-packages/gpiozero/pins/native.py", line 158, in __init__
    self.fd = os.open('/dev/mem', os.O_RDWR | os.O_SYNC)
              ^^^^^^^^^^^^^^^^^^^^^^^^^^^^^^^^^^^^^^^^^^
PermissionError: [Errno 13] Permission denied: '/dev/mem'

During handling of the above exception, another exception occurred:

Traceback (most recent call last):
  File "/home/torrobot/torrobot/control.py", line 9, in <module>
    Device.pin_factory = NativeFactory()
                         ^^^^^^^^^^^^^^^
  File "/home/torrobot/torrobot/venv/lib/python3.11/site-packages/gpiozero/pins/native.py", line 395, in __init__
    self.mem = GPIOMemory(self.board_info.soc)
               ^^^^^^^^^^^^^^^^^^^^^^^^^^^^^^^
  File "/home/torrobot/torrobot/venv/lib/python3.11/site-packages/gpiozero/pins/native.py", line 160, in __init__
    raise IOError(
OSError: unable to open /dev/gpiomem or /dev/mem; upgrade your kernel or run as root
Sat 21 Dec 07:09:38 GMT 2024: /home/torrobot/torrobot/control.py crashed with exit code 0; restarting in 5 seconds...
Sat 21 Dec 07:09:43 GMT 2024: Starting /home/torrobot/torrobot/control.py...
Traceback (most recent call last):
  File "/home/torrobot/torrobot/venv/lib/python3.11/site-packages/gpiozero/pins/native.py", line 155, in __init__
    self.fd = os.open('/dev/gpiomem', os.O_RDWR | os.O_SYNC)
              ^^^^^^^^^^^^^^^^^^^^^^^^^^^^^^^^^^^^^^^^^^^^^^
FileNotFoundError: [Errno 2] No such file or directory: '/dev/gpiomem'

During handling of the above exception, another exception occurred:

Traceback (most recent call last):
  File "/home/torrobot/torrobot/venv/lib/python3.11/site-packages/gpiozero/pins/native.py", line 158, in __init__
    self.fd = os.open('/dev/mem', os.O_RDWR | os.O_SYNC)
              ^^^^^^^^^^^^^^^^^^^^^^^^^^^^^^^^^^^^^^^^^^
PermissionError: [Errno 13] Permission denied: '/dev/mem'

During handling of the above exception, another exception occurred:

Traceback (most recent call last):
  File "/home/torrobot/torrobot/control.py", line 9, in <module>
    Device.pin_factory = NativeFactory()
                         ^^^^^^^^^^^^^^^
  File "/home/torrobot/torrobot/venv/lib/python3.11/site-packages/gpiozero/pins/native.py", line 395, in __init__
    self.mem = GPIOMemory(self.board_info.soc)
               ^^^^^^^^^^^^^^^^^^^^^^^^^^^^^^^
  File "/home/torrobot/torrobot/venv/lib/python3.11/site-packages/gpiozero/pins/native.py", line 160, in __init__
    raise IOError(
OSError: unable to open /dev/gpiomem or /dev/mem; upgrade your kernel or run as root
Sat 21 Dec 07:09:43 GMT 2024: /home/torrobot/torrobot/control.py crashed with exit code 0; restarting in 5 seconds...
Sat 21 Dec 07:09:48 GMT 2024: Starting /home/torrobot/torrobot/control.py...
Traceback (most recent call last):
  File "/home/torrobot/torrobot/venv/lib/python3.11/site-packages/gpiozero/pins/native.py", line 155, in __init__
    self.fd = os.open('/dev/gpiomem', os.O_RDWR | os.O_SYNC)
              ^^^^^^^^^^^^^^^^^^^^^^^^^^^^^^^^^^^^^^^^^^^^^^
FileNotFoundError: [Errno 2] No such file or directory: '/dev/gpiomem'

During handling of the above exception, another exception occurred:

Traceback (most recent call last):
  File "/home/torrobot/torrobot/venv/lib/python3.11/site-packages/gpiozero/pins/native.py", line 158, in __init__
    self.fd = os.open('/dev/mem', os.O_RDWR | os.O_SYNC)
              ^^^^^^^^^^^^^^^^^^^^^^^^^^^^^^^^^^^^^^^^^^
PermissionError: [Errno 13] Permission denied: '/dev/mem'

During handling of the above exception, another exception occurred:

Traceback (most recent call last):
  File "/home/torrobot/torrobot/control.py", line 9, in <module>
    Device.pin_factory = NativeFactory()
                         ^^^^^^^^^^^^^^^
  File "/home/torrobot/torrobot/venv/lib/python3.11/site-packages/gpiozero/pins/native.py", line 395, in __init__
    self.mem = GPIOMemory(self.board_info.soc)
               ^^^^^^^^^^^^^^^^^^^^^^^^^^^^^^^
  File "/home/torrobot/torrobot/venv/lib/python3.11/site-packages/gpiozero/pins/native.py", line 160, in __init__
    raise IOError(
OSError: unable to open /dev/gpiomem or /dev/mem; upgrade your kernel or run as root
Sat 21 Dec 07:09:49 GMT 2024: /home/torrobot/torrobot/control.py crashed with exit code 0; restarting in 5 seconds...
Sat 21 Dec 07:09:54 GMT 2024: Starting /home/torrobot/torrobot/control.py...
Traceback (most recent call last):
  File "/home/torrobot/torrobot/venv/lib/python3.11/site-packages/gpiozero/pins/native.py", line 155, in __init__
    self.fd = os.open('/dev/gpiomem', os.O_RDWR | os.O_SYNC)
              ^^^^^^^^^^^^^^^^^^^^^^^^^^^^^^^^^^^^^^^^^^^^^^
FileNotFoundError: [Errno 2] No such file or directory: '/dev/gpiomem'

During handling of the above exception, another exception occurred:

Traceback (most recent call last):
  File "/home/torrobot/torrobot/venv/lib/python3.11/site-packages/gpiozero/pins/native.py", line 158, in __init__
    self.fd = os.open('/dev/mem', os.O_RDWR | os.O_SYNC)
              ^^^^^^^^^^^^^^^^^^^^^^^^^^^^^^^^^^^^^^^^^^
PermissionError: [Errno 13] Permission denied: '/dev/mem'

During handling of the above exception, another exception occurred:

Traceback (most recent call last):
  File "/home/torrobot/torrobot/control.py", line 9, in <module>
    Device.pin_factory = NativeFactory()
                         ^^^^^^^^^^^^^^^
  File "/home/torrobot/torrobot/venv/lib/python3.11/site-packages/gpiozero/pins/native.py", line 395, in __init__
    self.mem = GPIOMemory(self.board_info.soc)
               ^^^^^^^^^^^^^^^^^^^^^^^^^^^^^^^
  File "/home/torrobot/torrobot/venv/lib/python3.11/site-packages/gpiozero/pins/native.py", line 160, in __init__
    raise IOError(
OSError: unable to open /dev/gpiomem or /dev/mem; upgrade your kernel or run as root
Sat 21 Dec 07:09:54 GMT 2024: /home/torrobot/torrobot/control.py crashed with exit code 0; restarting in 5 seconds...
Sat 21 Dec 07:09:59 GMT 2024: Starting /home/torrobot/torrobot/control.py...
Traceback (most recent call last):
  File "/home/torrobot/torrobot/venv/lib/python3.11/site-packages/gpiozero/pins/native.py", line 155, in __init__
    self.fd = os.open('/dev/gpiomem', os.O_RDWR | os.O_SYNC)
              ^^^^^^^^^^^^^^^^^^^^^^^^^^^^^^^^^^^^^^^^^^^^^^
FileNotFoundError: [Errno 2] No such file or directory: '/dev/gpiomem'

During handling of the above exception, another exception occurred:

Traceback (most recent call last):
  File "/home/torrobot/torrobot/venv/lib/python3.11/site-packages/gpiozero/pins/native.py", line 158, in __init__
    self.fd = os.open('/dev/mem', os.O_RDWR | os.O_SYNC)
              ^^^^^^^^^^^^^^^^^^^^^^^^^^^^^^^^^^^^^^^^^^
PermissionError: [Errno 13] Permission denied: '/dev/mem'

During handling of the above exception, another exception occurred:

Traceback (most recent call last):
  File "/home/torrobot/torrobot/control.py", line 9, in <module>
    servo = Servo(servo_pin, min_pulse_width=0.0005, max_pulse_width=0.0025)
            ^^^^^^^^^^^^^^^^^^^^^^^^^^^^^^^^^^^^^^^^^^^^^^^^^^^^^^^^^^^^^^^^
  File "/home/torrobot/torrobot/venv/lib/python3.11/site-packages/gpiozero/devices.py", line 108, in __call__
    self = super().__call__(*args, **kwargs)
           ^^^^^^^^^^^^^^^^^^^^^^^^^^^^^^^^^
  File "/home/torrobot/torrobot/venv/lib/python3.11/site-packages/gpiozero/output_devices.py", line 1503, in __init__
    pwm_device=PWMOutputDevice(
               ^^^^^^^^^^^^^^^^
  File "/home/torrobot/torrobot/venv/lib/python3.11/site-packages/gpiozero/devices.py", line 108, in __call__
    self = super().__call__(*args, **kwargs)
           ^^^^^^^^^^^^^^^^^^^^^^^^^^^^^^^^^
  File "/home/torrobot/torrobot/venv/lib/python3.11/site-packages/gpiozero/output_devices.py", line 392, in __init__
    super().__init__(pin, active_high=active_high, initial_value=None,
  File "/home/torrobot/torrobot/venv/lib/python3.11/site-packages/gpiozero/output_devices.py", line 74, in __init__
    super().__init__(pin, pin_factory=pin_factory)
  File "/home/torrobot/torrobot/venv/lib/python3.11/site-packages/gpiozero/mixins.py", line 75, in __init__
    super().__init__(*args, **kwargs)
  File "/home/torrobot/torrobot/venv/lib/python3.11/site-packages/gpiozero/devices.py", line 544, in __init__
    super().__init__(pin_factory=pin_factory)
  File "/home/torrobot/torrobot/venv/lib/python3.11/site-packages/gpiozero/devices.py", line 245, in __init__
    Device.ensure_pin_factory()
  File "/home/torrobot/torrobot/venv/lib/python3.11/site-packages/gpiozero/devices.py", line 270, in ensure_pin_factory
    Device.pin_factory = Device._default_pin_factory()
                         ^^^^^^^^^^^^^^^^^^^^^^^^^^^^^
  File "/home/torrobot/torrobot/venv/lib/python3.11/site-packages/gpiozero/devices.py", line 314, in _default_pin_factory
    return ep.load()()
           ^^^^^^^^^^^
  File "/home/torrobot/torrobot/venv/lib/python3.11/site-packages/gpiozero/pins/native.py", line 395, in __init__
    self.mem = GPIOMemory(self.board_info.soc)
               ^^^^^^^^^^^^^^^^^^^^^^^^^^^^^^^
  File "/home/torrobot/torrobot/venv/lib/python3.11/site-packages/gpiozero/pins/native.py", line 160, in __init__
    raise IOError(
OSError: unable to open /dev/gpiomem or /dev/mem; upgrade your kernel or run as root
Sat 21 Dec 07:09:59 GMT 2024: /home/torrobot/torrobot/control.py crashed with exit code 0; restarting in 5 seconds...
Sat 21 Dec 07:10:04 GMT 2024: Starting /home/torrobot/torrobot/control.py...
Traceback (most recent call last):
  File "/home/torrobot/torrobot/venv/lib/python3.11/site-packages/gpiozero/pins/native.py", line 155, in __init__
    self.fd = os.open('/dev/gpiomem', os.O_RDWR | os.O_SYNC)
              ^^^^^^^^^^^^^^^^^^^^^^^^^^^^^^^^^^^^^^^^^^^^^^
FileNotFoundError: [Errno 2] No such file or directory: '/dev/gpiomem'

During handling of the above exception, another exception occurred:

Traceback (most recent call last):
  File "/home/torrobot/torrobot/venv/lib/python3.11/site-packages/gpiozero/pins/native.py", line 158, in __init__
    self.fd = os.open('/dev/mem', os.O_RDWR | os.O_SYNC)
              ^^^^^^^^^^^^^^^^^^^^^^^^^^^^^^^^^^^^^^^^^^
PermissionError: [Errno 13] Permission denied: '/dev/mem'

During handling of the above exception, another exception occurred:

Traceback (most recent call last):
  File "/home/torrobot/torrobot/control.py", line 9, in <module>
    servo = Servo(servo_pin, min_pulse_width=0.0005, max_pulse_width=0.0025)
            ^^^^^^^^^^^^^^^^^^^^^^^^^^^^^^^^^^^^^^^^^^^^^^^^^^^^^^^^^^^^^^^^
  File "/home/torrobot/torrobot/venv/lib/python3.11/site-packages/gpiozero/devices.py", line 108, in __call__
    self = super().__call__(*args, **kwargs)
           ^^^^^^^^^^^^^^^^^^^^^^^^^^^^^^^^^
  File "/home/torrobot/torrobot/venv/lib/python3.11/site-packages/gpiozero/output_devices.py", line 1503, in __init__
    pwm_device=PWMOutputDevice(
               ^^^^^^^^^^^^^^^^
  File "/home/torrobot/torrobot/venv/lib/python3.11/site-packages/gpiozero/devices.py", line 108, in __call__
    self = super().__call__(*args, **kwargs)
           ^^^^^^^^^^^^^^^^^^^^^^^^^^^^^^^^^
  File "/home/torrobot/torrobot/venv/lib/python3.11/site-packages/gpiozero/output_devices.py", line 392, in __init__
    super().__init__(pin, active_high=active_high, initial_value=None,
  File "/home/torrobot/torrobot/venv/lib/python3.11/site-packages/gpiozero/output_devices.py", line 74, in __init__
    super().__init__(pin, pin_factory=pin_factory)
  File "/home/torrobot/torrobot/venv/lib/python3.11/site-packages/gpiozero/mixins.py", line 75, in __init__
    super().__init__(*args, **kwargs)
  File "/home/torrobot/torrobot/venv/lib/python3.11/site-packages/gpiozero/devices.py", line 544, in __init__
    super().__init__(pin_factory=pin_factory)
  File "/home/torrobot/torrobot/venv/lib/python3.11/site-packages/gpiozero/devices.py", line 245, in __init__
    Device.ensure_pin_factory()
  File "/home/torrobot/torrobot/venv/lib/python3.11/site-packages/gpiozero/devices.py", line 270, in ensure_pin_factory
    Device.pin_factory = Device._default_pin_factory()
                         ^^^^^^^^^^^^^^^^^^^^^^^^^^^^^
  File "/home/torrobot/torrobot/venv/lib/python3.11/site-packages/gpiozero/devices.py", line 314, in _default_pin_factory
    return ep.load()()
           ^^^^^^^^^^^
  File "/home/torrobot/torrobot/venv/lib/python3.11/site-packages/gpiozero/pins/native.py", line 395, in __init__
    self.mem = GPIOMemory(self.board_info.soc)
               ^^^^^^^^^^^^^^^^^^^^^^^^^^^^^^^
  File "/home/torrobot/torrobot/venv/lib/python3.11/site-packages/gpiozero/pins/native.py", line 160, in __init__
    raise IOError(
OSError: unable to open /dev/gpiomem or /dev/mem; upgrade your kernel or run as root
Sat 21 Dec 07:10:04 GMT 2024: /home/torrobot/torrobot/control.py crashed with exit code 0; restarting in 5 seconds...
Sat 21 Dec 07:10:09 GMT 2024: Starting /home/torrobot/torrobot/control.py...
Traceback (most recent call last):
  File "/home/torrobot/torrobot/venv/lib/python3.11/site-packages/gpiozero/pins/native.py", line 155, in __init__
    self.fd = os.open('/dev/gpiomem', os.O_RDWR | os.O_SYNC)
              ^^^^^^^^^^^^^^^^^^^^^^^^^^^^^^^^^^^^^^^^^^^^^^
FileNotFoundError: [Errno 2] No such file or directory: '/dev/gpiomem'

During handling of the above exception, another exception occurred:

Traceback (most recent call last):
  File "/home/torrobot/torrobot/venv/lib/python3.11/site-packages/gpiozero/pins/native.py", line 158, in __init__
    self.fd = os.open('/dev/mem', os.O_RDWR | os.O_SYNC)
              ^^^^^^^^^^^^^^^^^^^^^^^^^^^^^^^^^^^^^^^^^^
PermissionError: [Errno 13] Permission denied: '/dev/mem'

During handling of the above exception, another exception occurred:

Traceback (most recent call last):
  File "/home/torrobot/torrobot/control.py", line 9, in <module>
    servo = Servo(servo_pin, min_pulse_width=0.0005, max_pulse_width=0.0025)
            ^^^^^^^^^^^^^^^^^^^^^^^^^^^^^^^^^^^^^^^^^^^^^^^^^^^^^^^^^^^^^^^^
  File "/home/torrobot/torrobot/venv/lib/python3.11/site-packages/gpiozero/devices.py", line 108, in __call__
    self = super().__call__(*args, **kwargs)
           ^^^^^^^^^^^^^^^^^^^^^^^^^^^^^^^^^
  File "/home/torrobot/torrobot/venv/lib/python3.11/site-packages/gpiozero/output_devices.py", line 1503, in __init__
    pwm_device=PWMOutputDevice(
               ^^^^^^^^^^^^^^^^
  File "/home/torrobot/torrobot/venv/lib/python3.11/site-packages/gpiozero/devices.py", line 108, in __call__
    self = super().__call__(*args, **kwargs)
           ^^^^^^^^^^^^^^^^^^^^^^^^^^^^^^^^^
  File "/home/torrobot/torrobot/venv/lib/python3.11/site-packages/gpiozero/output_devices.py", line 392, in __init__
    super().__init__(pin, active_high=active_high, initial_value=None,
  File "/home/torrobot/torrobot/venv/lib/python3.11/site-packages/gpiozero/output_devices.py", line 74, in __init__
    super().__init__(pin, pin_factory=pin_factory)
  File "/home/torrobot/torrobot/venv/lib/python3.11/site-packages/gpiozero/mixins.py", line 75, in __init__
    super().__init__(*args, **kwargs)
  File "/home/torrobot/torrobot/venv/lib/python3.11/site-packages/gpiozero/devices.py", line 544, in __init__
    super().__init__(pin_factory=pin_factory)
  File "/home/torrobot/torrobot/venv/lib/python3.11/site-packages/gpiozero/devices.py", line 245, in __init__
    Device.ensure_pin_factory()
  File "/home/torrobot/torrobot/venv/lib/python3.11/site-packages/gpiozero/devices.py", line 270, in ensure_pin_factory
    Device.pin_factory = Device._default_pin_factory()
                         ^^^^^^^^^^^^^^^^^^^^^^^^^^^^^
  File "/home/torrobot/torrobot/venv/lib/python3.11/site-packages/gpiozero/devices.py", line 314, in _default_pin_factory
    return ep.load()()
           ^^^^^^^^^^^
  File "/home/torrobot/torrobot/venv/lib/python3.11/site-packages/gpiozero/pins/native.py", line 395, in __init__
    self.mem = GPIOMemory(self.board_info.soc)
               ^^^^^^^^^^^^^^^^^^^^^^^^^^^^^^^
  File "/home/torrobot/torrobot/venv/lib/python3.11/site-packages/gpiozero/pins/native.py", line 160, in __init__
    raise IOError(
OSError: unable to open /dev/gpiomem or /dev/mem; upgrade your kernel or run as root
Sat 21 Dec 07:10:09 GMT 2024: /home/torrobot/torrobot/control.py crashed with exit code 0; restarting in 5 seconds...
Sat 21 Dec 07:10:14 GMT 2024: Starting /home/torrobot/torrobot/control.py...
Traceback (most recent call last):
  File "/home/torrobot/torrobot/venv/lib/python3.11/site-packages/gpiozero/pins/native.py", line 155, in __init__
    self.fd = os.open('/dev/gpiomem', os.O_RDWR | os.O_SYNC)
              ^^^^^^^^^^^^^^^^^^^^^^^^^^^^^^^^^^^^^^^^^^^^^^
FileNotFoundError: [Errno 2] No such file or directory: '/dev/gpiomem'

During handling of the above exception, another exception occurred:

Traceback (most recent call last):
  File "/home/torrobot/torrobot/venv/lib/python3.11/site-packages/gpiozero/pins/native.py", line 158, in __init__
    self.fd = os.open('/dev/mem', os.O_RDWR | os.O_SYNC)
              ^^^^^^^^^^^^^^^^^^^^^^^^^^^^^^^^^^^^^^^^^^
PermissionError: [Errno 13] Permission denied: '/dev/mem'

During handling of the above exception, another exception occurred:

Traceback (most recent call last):
  File "/home/torrobot/torrobot/control.py", line 9, in <module>
    servo = Servo(servo_pin, min_pulse_width=0.0005, max_pulse_width=0.0025)
            ^^^^^^^^^^^^^^^^^^^^^^^^^^^^^^^^^^^^^^^^^^^^^^^^^^^^^^^^^^^^^^^^
  File "/home/torrobot/torrobot/venv/lib/python3.11/site-packages/gpiozero/devices.py", line 108, in __call__
    self = super().__call__(*args, **kwargs)
           ^^^^^^^^^^^^^^^^^^^^^^^^^^^^^^^^^
  File "/home/torrobot/torrobot/venv/lib/python3.11/site-packages/gpiozero/output_devices.py", line 1503, in __init__
    pwm_device=PWMOutputDevice(
               ^^^^^^^^^^^^^^^^
  File "/home/torrobot/torrobot/venv/lib/python3.11/site-packages/gpiozero/devices.py", line 108, in __call__
    self = super().__call__(*args, **kwargs)
           ^^^^^^^^^^^^^^^^^^^^^^^^^^^^^^^^^
  File "/home/torrobot/torrobot/venv/lib/python3.11/site-packages/gpiozero/output_devices.py", line 392, in __init__
    super().__init__(pin, active_high=active_high, initial_value=None,
  File "/home/torrobot/torrobot/venv/lib/python3.11/site-packages/gpiozero/output_devices.py", line 74, in __init__
    super().__init__(pin, pin_factory=pin_factory)
  File "/home/torrobot/torrobot/venv/lib/python3.11/site-packages/gpiozero/mixins.py", line 75, in __init__
    super().__init__(*args, **kwargs)
  File "/home/torrobot/torrobot/venv/lib/python3.11/site-packages/gpiozero/devices.py", line 544, in __init__
    super().__init__(pin_factory=pin_factory)
  File "/home/torrobot/torrobot/venv/lib/python3.11/site-packages/gpiozero/devices.py", line 245, in __init__
    Device.ensure_pin_factory()
  File "/home/torrobot/torrobot/venv/lib/python3.11/site-packages/gpiozero/devices.py", line 270, in ensure_pin_factory
    Device.pin_factory = Device._default_pin_factory()
                         ^^^^^^^^^^^^^^^^^^^^^^^^^^^^^
  File "/home/torrobot/torrobot/venv/lib/python3.11/site-packages/gpiozero/devices.py", line 314, in _default_pin_factory
    return ep.load()()
           ^^^^^^^^^^^
  File "/home/torrobot/torrobot/venv/lib/python3.11/site-packages/gpiozero/pins/native.py", line 395, in __init__
    self.mem = GPIOMemory(self.board_info.soc)
               ^^^^^^^^^^^^^^^^^^^^^^^^^^^^^^^
  File "/home/torrobot/torrobot/venv/lib/python3.11/site-packages/gpiozero/pins/native.py", line 160, in __init__
    raise IOError(
OSError: unable to open /dev/gpiomem or /dev/mem; upgrade your kernel or run as root
Sat 21 Dec 07:10:14 GMT 2024: /home/torrobot/torrobot/control.py crashed with exit code 0; restarting in 5 seconds...
Sat 21 Dec 07:10:19 GMT 2024: Starting /home/torrobot/torrobot/control.py...
Traceback (most recent call last):
  File "/home/torrobot/torrobot/venv/lib/python3.11/site-packages/gpiozero/pins/native.py", line 155, in __init__
    self.fd = os.open('/dev/gpiomem', os.O_RDWR | os.O_SYNC)
              ^^^^^^^^^^^^^^^^^^^^^^^^^^^^^^^^^^^^^^^^^^^^^^
FileNotFoundError: [Errno 2] No such file or directory: '/dev/gpiomem'

During handling of the above exception, another exception occurred:

Traceback (most recent call last):
  File "/home/torrobot/torrobot/venv/lib/python3.11/site-packages/gpiozero/pins/native.py", line 158, in __init__
    self.fd = os.open('/dev/mem', os.O_RDWR | os.O_SYNC)
              ^^^^^^^^^^^^^^^^^^^^^^^^^^^^^^^^^^^^^^^^^^
PermissionError: [Errno 13] Permission denied: '/dev/mem'

During handling of the above exception, another exception occurred:

Traceback (most recent call last):
  File "/home/torrobot/torrobot/control.py", line 9, in <module>
    servo = Servo(servo_pin, min_pulse_width=0.0005, max_pulse_width=0.0025)
            ^^^^^^^^^^^^^^^^^^^^^^^^^^^^^^^^^^^^^^^^^^^^^^^^^^^^^^^^^^^^^^^^
  File "/home/torrobot/torrobot/venv/lib/python3.11/site-packages/gpiozero/devices.py", line 108, in __call__
    self = super().__call__(*args, **kwargs)
           ^^^^^^^^^^^^^^^^^^^^^^^^^^^^^^^^^
  File "/home/torrobot/torrobot/venv/lib/python3.11/site-packages/gpiozero/output_devices.py", line 1503, in __init__
    pwm_device=PWMOutputDevice(
               ^^^^^^^^^^^^^^^^
  File "/home/torrobot/torrobot/venv/lib/python3.11/site-packages/gpiozero/devices.py", line 108, in __call__
    self = super().__call__(*args, **kwargs)
           ^^^^^^^^^^^^^^^^^^^^^^^^^^^^^^^^^
  File "/home/torrobot/torrobot/venv/lib/python3.11/site-packages/gpiozero/output_devices.py", line 392, in __init__
    super().__init__(pin, active_high=active_high, initial_value=None,
  File "/home/torrobot/torrobot/venv/lib/python3.11/site-packages/gpiozero/output_devices.py", line 74, in __init__
    super().__init__(pin, pin_factory=pin_factory)
  File "/home/torrobot/torrobot/venv/lib/python3.11/site-packages/gpiozero/mixins.py", line 75, in __init__
    super().__init__(*args, **kwargs)
  File "/home/torrobot/torrobot/venv/lib/python3.11/site-packages/gpiozero/devices.py", line 544, in __init__
    super().__init__(pin_factory=pin_factory)
  File "/home/torrobot/torrobot/venv/lib/python3.11/site-packages/gpiozero/devices.py", line 245, in __init__
    Device.ensure_pin_factory()
  File "/home/torrobot/torrobot/venv/lib/python3.11/site-packages/gpiozero/devices.py", line 270, in ensure_pin_factory
    Device.pin_factory = Device._default_pin_factory()
                         ^^^^^^^^^^^^^^^^^^^^^^^^^^^^^
  File "/home/torrobot/torrobot/venv/lib/python3.11/site-packages/gpiozero/devices.py", line 314, in _default_pin_factory
    return ep.load()()
           ^^^^^^^^^^^
  File "/home/torrobot/torrobot/venv/lib/python3.11/site-packages/gpiozero/pins/native.py", line 395, in __init__
    self.mem = GPIOMemory(self.board_info.soc)
               ^^^^^^^^^^^^^^^^^^^^^^^^^^^^^^^
  File "/home/torrobot/torrobot/venv/lib/python3.11/site-packages/gpiozero/pins/native.py", line 160, in __init__
    raise IOError(
OSError: unable to open /dev/gpiomem or /dev/mem; upgrade your kernel or run as root
Sat 21 Dec 07:10:20 GMT 2024: /home/torrobot/torrobot/control.py crashed with exit code 0; restarting in 5 seconds...
Sat 21 Dec 07:10:25 GMT 2024: Starting /home/torrobot/torrobot/control.py...
Traceback (most recent call last):
  File "/home/torrobot/torrobot/venv/lib/python3.11/site-packages/gpiozero/pins/native.py", line 155, in __init__
    self.fd = os.open('/dev/gpiomem', os.O_RDWR | os.O_SYNC)
              ^^^^^^^^^^^^^^^^^^^^^^^^^^^^^^^^^^^^^^^^^^^^^^
FileNotFoundError: [Errno 2] No such file or directory: '/dev/gpiomem'

During handling of the above exception, another exception occurred:

Traceback (most recent call last):
  File "/home/torrobot/torrobot/venv/lib/python3.11/site-packages/gpiozero/pins/native.py", line 158, in __init__
    self.fd = os.open('/dev/mem', os.O_RDWR | os.O_SYNC)
              ^^^^^^^^^^^^^^^^^^^^^^^^^^^^^^^^^^^^^^^^^^
PermissionError: [Errno 13] Permission denied: '/dev/mem'

During handling of the above exception, another exception occurred:

Traceback (most recent call last):
  File "/home/torrobot/torrobot/control.py", line 9, in <module>
    servo = Servo(servo_pin, min_pulse_width=0.0005, max_pulse_width=0.0025)
            ^^^^^^^^^^^^^^^^^^^^^^^^^^^^^^^^^^^^^^^^^^^^^^^^^^^^^^^^^^^^^^^^
  File "/home/torrobot/torrobot/venv/lib/python3.11/site-packages/gpiozero/devices.py", line 108, in __call__
    self = super().__call__(*args, **kwargs)
           ^^^^^^^^^^^^^^^^^^^^^^^^^^^^^^^^^
  File "/home/torrobot/torrobot/venv/lib/python3.11/site-packages/gpiozero/output_devices.py", line 1503, in __init__
    pwm_device=PWMOutputDevice(
               ^^^^^^^^^^^^^^^^
  File "/home/torrobot/torrobot/venv/lib/python3.11/site-packages/gpiozero/devices.py", line 108, in __call__
    self = super().__call__(*args, **kwargs)
           ^^^^^^^^^^^^^^^^^^^^^^^^^^^^^^^^^
  File "/home/torrobot/torrobot/venv/lib/python3.11/site-packages/gpiozero/output_devices.py", line 392, in __init__
    super().__init__(pin, active_high=active_high, initial_value=None,
  File "/home/torrobot/torrobot/venv/lib/python3.11/site-packages/gpiozero/output_devices.py", line 74, in __init__
    super().__init__(pin, pin_factory=pin_factory)
  File "/home/torrobot/torrobot/venv/lib/python3.11/site-packages/gpiozero/mixins.py", line 75, in __init__
    super().__init__(*args, **kwargs)
  File "/home/torrobot/torrobot/venv/lib/python3.11/site-packages/gpiozero/devices.py", line 544, in __init__
    super().__init__(pin_factory=pin_factory)
  File "/home/torrobot/torrobot/venv/lib/python3.11/site-packages/gpiozero/devices.py", line 245, in __init__
    Device.ensure_pin_factory()
  File "/home/torrobot/torrobot/venv/lib/python3.11/site-packages/gpiozero/devices.py", line 270, in ensure_pin_factory
    Device.pin_factory = Device._default_pin_factory()
                         ^^^^^^^^^^^^^^^^^^^^^^^^^^^^^
  File "/home/torrobot/torrobot/venv/lib/python3.11/site-packages/gpiozero/devices.py", line 314, in _default_pin_factory
    return ep.load()()
           ^^^^^^^^^^^
  File "/home/torrobot/torrobot/venv/lib/python3.11/site-packages/gpiozero/pins/native.py", line 395, in __init__
    self.mem = GPIOMemory(self.board_info.soc)
               ^^^^^^^^^^^^^^^^^^^^^^^^^^^^^^^
  File "/home/torrobot/torrobot/venv/lib/python3.11/site-packages/gpiozero/pins/native.py", line 160, in __init__
    raise IOError(
OSError: unable to open /dev/gpiomem or /dev/mem; upgrade your kernel or run as root
Sat 21 Dec 07:10:25 GMT 2024: /home/torrobot/torrobot/control.py crashed with exit code 0; restarting in 5 seconds...
Sat 21 Dec 07:10:30 GMT 2024: Starting /home/torrobot/torrobot/control.py...
Traceback (most recent call last):
  File "/home/torrobot/torrobot/venv/lib/python3.11/site-packages/gpiozero/pins/native.py", line 155, in __init__
    self.fd = os.open('/dev/gpiomem', os.O_RDWR | os.O_SYNC)
              ^^^^^^^^^^^^^^^^^^^^^^^^^^^^^^^^^^^^^^^^^^^^^^
FileNotFoundError: [Errno 2] No such file or directory: '/dev/gpiomem'

During handling of the above exception, another exception occurred:

Traceback (most recent call last):
  File "/home/torrobot/torrobot/venv/lib/python3.11/site-packages/gpiozero/pins/native.py", line 158, in __init__
    self.fd = os.open('/dev/mem', os.O_RDWR | os.O_SYNC)
              ^^^^^^^^^^^^^^^^^^^^^^^^^^^^^^^^^^^^^^^^^^
PermissionError: [Errno 13] Permission denied: '/dev/mem'

During handling of the above exception, another exception occurred:

Traceback (most recent call last):
  File "/home/torrobot/torrobot/control.py", line 9, in <module>
    servo = Servo(servo_pin, min_pulse_width=0.0005, max_pulse_width=0.0025)
            ^^^^^^^^^^^^^^^^^^^^^^^^^^^^^^^^^^^^^^^^^^^^^^^^^^^^^^^^^^^^^^^^
  File "/home/torrobot/torrobot/venv/lib/python3.11/site-packages/gpiozero/devices.py", line 108, in __call__
    self = super().__call__(*args, **kwargs)
           ^^^^^^^^^^^^^^^^^^^^^^^^^^^^^^^^^
  File "/home/torrobot/torrobot/venv/lib/python3.11/site-packages/gpiozero/output_devices.py", line 1503, in __init__
    pwm_device=PWMOutputDevice(
               ^^^^^^^^^^^^^^^^
  File "/home/torrobot/torrobot/venv/lib/python3.11/site-packages/gpiozero/devices.py", line 108, in __call__
    self = super().__call__(*args, **kwargs)
           ^^^^^^^^^^^^^^^^^^^^^^^^^^^^^^^^^
  File "/home/torrobot/torrobot/venv/lib/python3.11/site-packages/gpiozero/output_devices.py", line 392, in __init__
    super().__init__(pin, active_high=active_high, initial_value=None,
  File "/home/torrobot/torrobot/venv/lib/python3.11/site-packages/gpiozero/output_devices.py", line 74, in __init__
    super().__init__(pin, pin_factory=pin_factory)
  File "/home/torrobot/torrobot/venv/lib/python3.11/site-packages/gpiozero/mixins.py", line 75, in __init__
    super().__init__(*args, **kwargs)
  File "/home/torrobot/torrobot/venv/lib/python3.11/site-packages/gpiozero/devices.py", line 544, in __init__
    super().__init__(pin_factory=pin_factory)
  File "/home/torrobot/torrobot/venv/lib/python3.11/site-packages/gpiozero/devices.py", line 245, in __init__
    Device.ensure_pin_factory()
  File "/home/torrobot/torrobot/venv/lib/python3.11/site-packages/gpiozero/devices.py", line 270, in ensure_pin_factory
    Device.pin_factory = Device._default_pin_factory()
                         ^^^^^^^^^^^^^^^^^^^^^^^^^^^^^
  File "/home/torrobot/torrobot/venv/lib/python3.11/site-packages/gpiozero/devices.py", line 314, in _default_pin_factory
    return ep.load()()
           ^^^^^^^^^^^
  File "/home/torrobot/torrobot/venv/lib/python3.11/site-packages/gpiozero/pins/native.py", line 395, in __init__
    self.mem = GPIOMemory(self.board_info.soc)
               ^^^^^^^^^^^^^^^^^^^^^^^^^^^^^^^
  File "/home/torrobot/torrobot/venv/lib/python3.11/site-packages/gpiozero/pins/native.py", line 160, in __init__
    raise IOError(
OSError: unable to open /dev/gpiomem or /dev/mem; upgrade your kernel or run as root
Sat 21 Dec 07:10:30 GMT 2024: /home/torrobot/torrobot/control.py crashed with exit code 0; restarting in 5 seconds...
Sat 21 Dec 07:10:35 GMT 2024: Starting /home/torrobot/torrobot/control.py...
Traceback (most recent call last):
  File "/home/torrobot/torrobot/venv/lib/python3.11/site-packages/gpiozero/pins/native.py", line 155, in __init__
    self.fd = os.open('/dev/gpiomem', os.O_RDWR | os.O_SYNC)
              ^^^^^^^^^^^^^^^^^^^^^^^^^^^^^^^^^^^^^^^^^^^^^^
FileNotFoundError: [Errno 2] No such file or directory: '/dev/gpiomem'

During handling of the above exception, another exception occurred:

Traceback (most recent call last):
  File "/home/torrobot/torrobot/venv/lib/python3.11/site-packages/gpiozero/pins/native.py", line 158, in __init__
    self.fd = os.open('/dev/mem', os.O_RDWR | os.O_SYNC)
              ^^^^^^^^^^^^^^^^^^^^^^^^^^^^^^^^^^^^^^^^^^
PermissionError: [Errno 13] Permission denied: '/dev/mem'

During handling of the above exception, another exception occurred:

Traceback (most recent call last):
  File "/home/torrobot/torrobot/control.py", line 9, in <module>
    servo = Servo(servo_pin, min_pulse_width=0.0005, max_pulse_width=0.0025)
            ^^^^^^^^^^^^^^^^^^^^^^^^^^^^^^^^^^^^^^^^^^^^^^^^^^^^^^^^^^^^^^^^
  File "/home/torrobot/torrobot/venv/lib/python3.11/site-packages/gpiozero/devices.py", line 108, in __call__
    self = super().__call__(*args, **kwargs)
           ^^^^^^^^^^^^^^^^^^^^^^^^^^^^^^^^^
  File "/home/torrobot/torrobot/venv/lib/python3.11/site-packages/gpiozero/output_devices.py", line 1503, in __init__
    pwm_device=PWMOutputDevice(
               ^^^^^^^^^^^^^^^^
  File "/home/torrobot/torrobot/venv/lib/python3.11/site-packages/gpiozero/devices.py", line 108, in __call__
    self = super().__call__(*args, **kwargs)
           ^^^^^^^^^^^^^^^^^^^^^^^^^^^^^^^^^
  File "/home/torrobot/torrobot/venv/lib/python3.11/site-packages/gpiozero/output_devices.py", line 392, in __init__
    super().__init__(pin, active_high=active_high, initial_value=None,
  File "/home/torrobot/torrobot/venv/lib/python3.11/site-packages/gpiozero/output_devices.py", line 74, in __init__
    super().__init__(pin, pin_factory=pin_factory)
  File "/home/torrobot/torrobot/venv/lib/python3.11/site-packages/gpiozero/mixins.py", line 75, in __init__
    super().__init__(*args, **kwargs)
  File "/home/torrobot/torrobot/venv/lib/python3.11/site-packages/gpiozero/devices.py", line 544, in __init__
    super().__init__(pin_factory=pin_factory)
  File "/home/torrobot/torrobot/venv/lib/python3.11/site-packages/gpiozero/devices.py", line 245, in __init__
    Device.ensure_pin_factory()
  File "/home/torrobot/torrobot/venv/lib/python3.11/site-packages/gpiozero/devices.py", line 270, in ensure_pin_factory
    Device.pin_factory = Device._default_pin_factory()
                         ^^^^^^^^^^^^^^^^^^^^^^^^^^^^^
  File "/home/torrobot/torrobot/venv/lib/python3.11/site-packages/gpiozero/devices.py", line 314, in _default_pin_factory
    return ep.load()()
           ^^^^^^^^^^^
  File "/home/torrobot/torrobot/venv/lib/python3.11/site-packages/gpiozero/pins/native.py", line 395, in __init__
    self.mem = GPIOMemory(self.board_info.soc)
               ^^^^^^^^^^^^^^^^^^^^^^^^^^^^^^^
  File "/home/torrobot/torrobot/venv/lib/python3.11/site-packages/gpiozero/pins/native.py", line 160, in __init__
    raise IOError(
OSError: unable to open /dev/gpiomem or /dev/mem; upgrade your kernel or run as root
Sat 21 Dec 07:10:35 GMT 2024: /home/torrobot/torrobot/control.py crashed with exit code 0; restarting in 5 seconds...
Sat 21 Dec 07:10:40 GMT 2024: Starting /home/torrobot/torrobot/control.py...
Traceback (most recent call last):
  File "/home/torrobot/torrobot/venv/lib/python3.11/site-packages/gpiozero/pins/native.py", line 155, in __init__
    self.fd = os.open('/dev/gpiomem', os.O_RDWR | os.O_SYNC)
              ^^^^^^^^^^^^^^^^^^^^^^^^^^^^^^^^^^^^^^^^^^^^^^
FileNotFoundError: [Errno 2] No such file or directory: '/dev/gpiomem'

During handling of the above exception, another exception occurred:

Traceback (most recent call last):
  File "/home/torrobot/torrobot/venv/lib/python3.11/site-packages/gpiozero/pins/native.py", line 158, in __init__
    self.fd = os.open('/dev/mem', os.O_RDWR | os.O_SYNC)
              ^^^^^^^^^^^^^^^^^^^^^^^^^^^^^^^^^^^^^^^^^^
PermissionError: [Errno 13] Permission denied: '/dev/mem'

During handling of the above exception, another exception occurred:

Traceback (most recent call last):
  File "/home/torrobot/torrobot/control.py", line 9, in <module>
    servo = Servo(servo_pin, min_pulse_width=0.0005, max_pulse_width=0.0025)
            ^^^^^^^^^^^^^^^^^^^^^^^^^^^^^^^^^^^^^^^^^^^^^^^^^^^^^^^^^^^^^^^^
  File "/home/torrobot/torrobot/venv/lib/python3.11/site-packages/gpiozero/devices.py", line 108, in __call__
    self = super().__call__(*args, **kwargs)
           ^^^^^^^^^^^^^^^^^^^^^^^^^^^^^^^^^
  File "/home/torrobot/torrobot/venv/lib/python3.11/site-packages/gpiozero/output_devices.py", line 1503, in __init__
    pwm_device=PWMOutputDevice(
               ^^^^^^^^^^^^^^^^
  File "/home/torrobot/torrobot/venv/lib/python3.11/site-packages/gpiozero/devices.py", line 108, in __call__
    self = super().__call__(*args, **kwargs)
           ^^^^^^^^^^^^^^^^^^^^^^^^^^^^^^^^^
  File "/home/torrobot/torrobot/venv/lib/python3.11/site-packages/gpiozero/output_devices.py", line 392, in __init__
    super().__init__(pin, active_high=active_high, initial_value=None,
  File "/home/torrobot/torrobot/venv/lib/python3.11/site-packages/gpiozero/output_devices.py", line 74, in __init__
    super().__init__(pin, pin_factory=pin_factory)
  File "/home/torrobot/torrobot/venv/lib/python3.11/site-packages/gpiozero/mixins.py", line 75, in __init__
    super().__init__(*args, **kwargs)
  File "/home/torrobot/torrobot/venv/lib/python3.11/site-packages/gpiozero/devices.py", line 544, in __init__
    super().__init__(pin_factory=pin_factory)
  File "/home/torrobot/torrobot/venv/lib/python3.11/site-packages/gpiozero/devices.py", line 245, in __init__
    Device.ensure_pin_factory()
  File "/home/torrobot/torrobot/venv/lib/python3.11/site-packages/gpiozero/devices.py", line 270, in ensure_pin_factory
    Device.pin_factory = Device._default_pin_factory()
                         ^^^^^^^^^^^^^^^^^^^^^^^^^^^^^
  File "/home/torrobot/torrobot/venv/lib/python3.11/site-packages/gpiozero/devices.py", line 314, in _default_pin_factory
    return ep.load()()
           ^^^^^^^^^^^
  File "/home/torrobot/torrobot/venv/lib/python3.11/site-packages/gpiozero/pins/native.py", line 395, in __init__
    self.mem = GPIOMemory(self.board_info.soc)
               ^^^^^^^^^^^^^^^^^^^^^^^^^^^^^^^
  File "/home/torrobot/torrobot/venv/lib/python3.11/site-packages/gpiozero/pins/native.py", line 160, in __init__
    raise IOError(
OSError: unable to open /dev/gpiomem or /dev/mem; upgrade your kernel or run as root
Sat 21 Dec 07:10:40 GMT 2024: /home/torrobot/torrobot/control.py crashed with exit code 0; restarting in 5 seconds...
Sat 21 Dec 07:10:45 GMT 2024: Starting /home/torrobot/torrobot/control.py...
Traceback (most recent call last):
  File "/home/torrobot/torrobot/venv/lib/python3.11/site-packages/gpiozero/pins/native.py", line 155, in __init__
    self.fd = os.open('/dev/gpiomem', os.O_RDWR | os.O_SYNC)
              ^^^^^^^^^^^^^^^^^^^^^^^^^^^^^^^^^^^^^^^^^^^^^^
FileNotFoundError: [Errno 2] No such file or directory: '/dev/gpiomem'

During handling of the above exception, another exception occurred:

Traceback (most recent call last):
  File "/home/torrobot/torrobot/venv/lib/python3.11/site-packages/gpiozero/pins/native.py", line 158, in __init__
    self.fd = os.open('/dev/mem', os.O_RDWR | os.O_SYNC)
              ^^^^^^^^^^^^^^^^^^^^^^^^^^^^^^^^^^^^^^^^^^
PermissionError: [Errno 13] Permission denied: '/dev/mem'

During handling of the above exception, another exception occurred:

Traceback (most recent call last):
  File "/home/torrobot/torrobot/control.py", line 9, in <module>
    servo = Servo(servo_pin, min_pulse_width=0.0005, max_pulse_width=0.0025)
            ^^^^^^^^^^^^^^^^^^^^^^^^^^^^^^^^^^^^^^^^^^^^^^^^^^^^^^^^^^^^^^^^
  File "/home/torrobot/torrobot/venv/lib/python3.11/site-packages/gpiozero/devices.py", line 108, in __call__
    self = super().__call__(*args, **kwargs)
           ^^^^^^^^^^^^^^^^^^^^^^^^^^^^^^^^^
  File "/home/torrobot/torrobot/venv/lib/python3.11/site-packages/gpiozero/output_devices.py", line 1503, in __init__
    pwm_device=PWMOutputDevice(
               ^^^^^^^^^^^^^^^^
  File "/home/torrobot/torrobot/venv/lib/python3.11/site-packages/gpiozero/devices.py", line 108, in __call__
    self = super().__call__(*args, **kwargs)
           ^^^^^^^^^^^^^^^^^^^^^^^^^^^^^^^^^
  File "/home/torrobot/torrobot/venv/lib/python3.11/site-packages/gpiozero/output_devices.py", line 392, in __init__
    super().__init__(pin, active_high=active_high, initial_value=None,
  File "/home/torrobot/torrobot/venv/lib/python3.11/site-packages/gpiozero/output_devices.py", line 74, in __init__
    super().__init__(pin, pin_factory=pin_factory)
  File "/home/torrobot/torrobot/venv/lib/python3.11/site-packages/gpiozero/mixins.py", line 75, in __init__
    super().__init__(*args, **kwargs)
  File "/home/torrobot/torrobot/venv/lib/python3.11/site-packages/gpiozero/devices.py", line 544, in __init__
    super().__init__(pin_factory=pin_factory)
  File "/home/torrobot/torrobot/venv/lib/python3.11/site-packages/gpiozero/devices.py", line 245, in __init__
    Device.ensure_pin_factory()
  File "/home/torrobot/torrobot/venv/lib/python3.11/site-packages/gpiozero/devices.py", line 270, in ensure_pin_factory
    Device.pin_factory = Device._default_pin_factory()
                         ^^^^^^^^^^^^^^^^^^^^^^^^^^^^^
  File "/home/torrobot/torrobot/venv/lib/python3.11/site-packages/gpiozero/devices.py", line 314, in _default_pin_factory
    return ep.load()()
           ^^^^^^^^^^^
  File "/home/torrobot/torrobot/venv/lib/python3.11/site-packages/gpiozero/pins/native.py", line 395, in __init__
    self.mem = GPIOMemory(self.board_info.soc)
               ^^^^^^^^^^^^^^^^^^^^^^^^^^^^^^^
  File "/home/torrobot/torrobot/venv/lib/python3.11/site-packages/gpiozero/pins/native.py", line 160, in __init__
    raise IOError(
OSError: unable to open /dev/gpiomem or /dev/mem; upgrade your kernel or run as root
Sat 21 Dec 07:10:46 GMT 2024: /home/torrobot/torrobot/control.py crashed with exit code 0; restarting in 5 seconds...
Sat 21 Dec 07:10:51 GMT 2024: Starting /home/torrobot/torrobot/control.py...
Traceback (most recent call last):
  File "/home/torrobot/torrobot/venv/lib/python3.11/site-packages/gpiozero/pins/native.py", line 155, in __init__
    self.fd = os.open('/dev/gpiomem', os.O_RDWR | os.O_SYNC)
              ^^^^^^^^^^^^^^^^^^^^^^^^^^^^^^^^^^^^^^^^^^^^^^
FileNotFoundError: [Errno 2] No such file or directory: '/dev/gpiomem'

During handling of the above exception, another exception occurred:

Traceback (most recent call last):
  File "/home/torrobot/torrobot/venv/lib/python3.11/site-packages/gpiozero/pins/native.py", line 158, in __init__
    self.fd = os.open('/dev/mem', os.O_RDWR | os.O_SYNC)
              ^^^^^^^^^^^^^^^^^^^^^^^^^^^^^^^^^^^^^^^^^^
PermissionError: [Errno 13] Permission denied: '/dev/mem'

During handling of the above exception, another exception occurred:

Traceback (most recent call last):
  File "/home/torrobot/torrobot/control.py", line 9, in <module>
    servo = Servo(servo_pin, min_pulse_width=0.0005, max_pulse_width=0.0025)
            ^^^^^^^^^^^^^^^^^^^^^^^^^^^^^^^^^^^^^^^^^^^^^^^^^^^^^^^^^^^^^^^^
  File "/home/torrobot/torrobot/venv/lib/python3.11/site-packages/gpiozero/devices.py", line 108, in __call__
    self = super().__call__(*args, **kwargs)
           ^^^^^^^^^^^^^^^^^^^^^^^^^^^^^^^^^
  File "/home/torrobot/torrobot/venv/lib/python3.11/site-packages/gpiozero/output_devices.py", line 1503, in __init__
    pwm_device=PWMOutputDevice(
               ^^^^^^^^^^^^^^^^
  File "/home/torrobot/torrobot/venv/lib/python3.11/site-packages/gpiozero/devices.py", line 108, in __call__
    self = super().__call__(*args, **kwargs)
           ^^^^^^^^^^^^^^^^^^^^^^^^^^^^^^^^^
  File "/home/torrobot/torrobot/venv/lib/python3.11/site-packages/gpiozero/output_devices.py", line 392, in __init__
    super().__init__(pin, active_high=active_high, initial_value=None,
  File "/home/torrobot/torrobot/venv/lib/python3.11/site-packages/gpiozero/output_devices.py", line 74, in __init__
    super().__init__(pin, pin_factory=pin_factory)
  File "/home/torrobot/torrobot/venv/lib/python3.11/site-packages/gpiozero/mixins.py", line 75, in __init__
    super().__init__(*args, **kwargs)
  File "/home/torrobot/torrobot/venv/lib/python3.11/site-packages/gpiozero/devices.py", line 544, in __init__
    super().__init__(pin_factory=pin_factory)
  File "/home/torrobot/torrobot/venv/lib/python3.11/site-packages/gpiozero/devices.py", line 245, in __init__
    Device.ensure_pin_factory()
  File "/home/torrobot/torrobot/venv/lib/python3.11/site-packages/gpiozero/devices.py", line 270, in ensure_pin_factory
    Device.pin_factory = Device._default_pin_factory()
                         ^^^^^^^^^^^^^^^^^^^^^^^^^^^^^
  File "/home/torrobot/torrobot/venv/lib/python3.11/site-packages/gpiozero/devices.py", line 314, in _default_pin_factory
    return ep.load()()
           ^^^^^^^^^^^
  File "/home/torrobot/torrobot/venv/lib/python3.11/site-packages/gpiozero/pins/native.py", line 395, in __init__
    self.mem = GPIOMemory(self.board_info.soc)
               ^^^^^^^^^^^^^^^^^^^^^^^^^^^^^^^
  File "/home/torrobot/torrobot/venv/lib/python3.11/site-packages/gpiozero/pins/native.py", line 160, in __init__
    raise IOError(
OSError: unable to open /dev/gpiomem or /dev/mem; upgrade your kernel or run as root
Sat 21 Dec 07:10:51 GMT 2024: /home/torrobot/torrobot/control.py crashed with exit code 0; restarting in 5 seconds...
